## 参数获取与LinValidator校验器
[linvalidator](http://doc.cms.7yue.pro/lin/server/koa/validator.html#%E4%BD%BF%E7%94%A8)
[validator-npm](https://www.npmjs.com/package/validator)
## 异常理论与异常链
1/0 
0/0
```js
function fun1(){
  try{
    fun2()
  }catch(err){
    throw err
  }
}

function fun2(){
  try{
    fun3()
  }catch(err){
    throw err
  }
}


function fun3 () {
  try {
    console.log(0/a)
  } catch (err){
    throw err
  }
  return 'success'
}

fun1()
// console.log(fun3())
// 没有发生异常 正确返回结果
// 发生了异常

// 函数设计
// 判断出异常 return false null  会丢失异常信息
// throw new Error 编程规范 throw
```
 
## 异步异常处理方案

> try catch无法捕捉异步异常
> 全局异常处理 异常 Promise Async 回调
> 结论 只要函数返回的是Promise 就用async 和 await 来简化

```js
function fun1(){
  try{
    fun2()
  }catch(err){
    throw err
  }
}

function fun2(){
  try{
    fun3()
  }catch(err){
    console.log('error')
  }
}

//全局异常处理
function fun3 () {
  setTimeout(()=>{
    throw new Error('error')
  },1000)
  return
}

fun1()
```

> koa库 包 axios sequelize都是promise形式
```js
async function fun2(){
  try{
    await fun3()
  }catch(err){
    console.log(err)
  }
}
function fun3 () {
  return new Promise((resolve,reject)=>{
    setTimeout(()=>{
      const r = Math.random()
      console.log(r)
      if(r<0.5){
        reject('error async')
      }
    })
  })
}
fun2()
```
## 全局异常处理中间件编写

> Unhandleed promise没有对promise报出的异常做出处理
```js
// middleware/expection.js
//AOP 面向切面编程
// 监听错误
// 输出一段有意义的提示信息
const catchError = async (ctx,next)=>{
   try {
     await next()
   } catch(error){
     ctx.body = {
       errDesc:'服务器有点问题'
     }
   }
}

module.exports = catchError
```

## 已知错误与未知错误
```js
// error 堆栈调用信息
// error 简化 清晰明了的信息
// HTTP Status Code 2xx, 4xx, 5xx
//message 
//error_code 详细 开发者自己定义 10001 20003
// request_url 当前请求url

// 已知错误 param int 'abc' lin  已知
// 处理错误 ，明确
// 自己try catch 处理错误明确

// 未知错误 程序潜在错误 无意识 根本就不知道错了
// 连接数据库 账号 密码 错误
```

## 定义异常返回格式
```js
const catchError = async (ctx,next)=>{
   try {
     await next()
   } catch(error){
     if(error.errorCode){
       ctx.body = {
         msg:error.message,
         error_code:error.errorCode,
         request:error.requestUrl
       }
       ctx.status = error.status
     }
   }
}

module.exports = catchError
```
## 定义HttpException异常基类
```js
// catcherror.js
const {HttpException} = require('../core/http-exception')
const catchError = async (ctx,next)=>{
   try {
     await next()
   } catch(error){
     if(error instanceof HttpException){
       ctx.body = {
         msg:error.msg,
         error_code:error.errorCode,
         request:`${ctx.method} ${ctx.path}`
       }
       ctx.status = error.code
     }
   }
}

module.exports = catchError
//http-exception.js
class HttpException extends Error{
  constructor(msg='服务器异常',errorCode=10000,code=400){
    super()
    this.errorCode = errorCode
    this.code = code
    this.msg = msg
  }
}

module.exports =  {HttpException}
```

## 特定异常类与global全局变量
```js
//init.js
static initCore(app){
      //入口方法
      InitManager.app = app
      InitManager.initLoadRouters()
      InitManager.loadHttpException()
}
static loadHttpException(){
      const errors = require('./http-exception')
      global.errs = errors
}
//使用
//const error = new global.errors.ParameterException()
// throw error
```